(doc try)
>> [body catch-clause* finally-clause?]
catch-clause => ('catch' class name body)
finally-clause => ('finally' body)
If an exception occurs in body and catch-clauses are provided, the first for which the thrown exception is an instance of the class is considered a matching catch-clause. Exception is stored as name.If there is no matching catch-clause, the exception propagates out of the function. If finally-clause is provided, it will be executed finally.
(try)
>> ERROR: cz.bh.lisp.LispException: Exception while evaluating function 'try', on line: 2:
    java.lang.IllegalArgumentException: Expected number of parameters: 1+, but was: 0
(try (/ 5 0))
>> ERROR: cz.bh.lisp.LispException: Exception while evaluating function 'try', on line: 3:
    cz.bh.lisp.LispException: Exception while evaluating function '/', on line: 3:
    java.lang.ArithmeticException: Division by zero
(try (finally (print "xxx")))
>> ERROR: cz.bh.lisp.LispException: Exception while evaluating function 'try', on line: 4:
    cz.bh.lisp.LispException: Symbol not defined: 'finally', on line: 4
(try (catch @java.lang.ArithmeticException e (print e)))
>> ERROR: cz.bh.lisp.LispException: Exception while evaluating function 'try', on line: 5:
    cz.bh.lisp.LispException: Symbol not defined: 'catch', on line: 5

(try (/ 5 0) (catch @java.lang.ArithmeticException e 1) (finally (print "exception occured")))
exception occured>> 1

(try (/ 5 0) (finally (print "xxx")))
xxx>> ERROR: cz.bh.lisp.LispException: Exception while evaluating function 'try', on line: 9:
    cz.bh.lisp.LispException: Exception while evaluating function '/', on line: 9:
    java.lang.ArithmeticException: Division by zero

(try (/ 5 0) (catch @java.lang.ArithmeticException e))
>> ERROR: cz.bh.lisp.LispException: Exception while evaluating function 'try', on line: 11:
    cz.bh.lisp.LispException: Exception in catch-clause, on line: 11:
    java.lang.IllegalArgumentException: Expected number of parameters: 4, but was: 3

(try (/ 5 0) (catch @java.lang.ArithmeticException e e))
>> java.lang.ArithmeticException: Division by zero

(try (/ 5 0) (catch @java.lang.ArithmeticException e nil))
>> nil



(doc throw)
>> [message] or [instance] Throws LispException with given message or instance of Throwable.
(throw)
>> ERROR: cz.bh.lisp.LispException: Exception while evaluating function 'throw', on line: 20:
    java.lang.IllegalArgumentException: Expected number of parameters: 1, but was: 0
(throw a d)
>> ERROR: cz.bh.lisp.LispException: Exception while evaluating function 'throw', on line: 21:
    java.lang.IllegalArgumentException: Expected number of parameters: 1, but was: 2
(throw e)
>> ERROR: cz.bh.lisp.LispException: Exception while evaluating function 'throw', on line: 22:
    cz.bh.lisp.LispException: Symbol not defined: 'e', on line: 22
(throw "hello")
>> ERROR: cz.bh.lisp.LispException: Exception while evaluating function 'throw', on line: 23:
    cz.bh.lisp.LispException: hello

(/ 5 0)
>> ERROR: cz.bh.lisp.LispException: Exception while evaluating function '/', on line: 25:
    java.lang.ArithmeticException: Division by zero
(try (/ 5 0) (catch @java.lang.ArithmeticException e (throw e)))
>> ERROR: cz.bh.lisp.LispException: Exception while evaluating function 'try', on line: 26:
    cz.bh.lisp.LispException: Exception while evaluating function 'throw', on line: 26:
    java.lang.ArithmeticException: Division by zero

(try (+ (/ (+ 5 1) 0) 5) (catch @java.lang.ArithmeticException e nil))
>> nil

(try (throw "hello") (catch @cz.bh.lisp.LispException e (. getMessage e)))
>> hello